---
title: 异步代码规范
date: 2020-07-20 20:06:11
categories: 前端
tags: 
    - 异步
---

### 序
异步回调的一个很大的问题在于callback hell也就是“回调地狱”。多层嵌套回调函数，严重影响代码规范，所以Promise的出现就是为了解决callback hell，在前端应用中得到广泛的应用，所以想要用好它还得遵循它的规范。下面结合最近做的需求做了一些总结，对其加深印象：

### Promise链式调用

- 各个task相互独立

> 如果想实现Promise的链式调用，要求每次链式调用都要返回一个Promise，所以每个异步执行都要使用Promise包装

```javascript

//bad
function task1(){
   return new Promise((resolve,reject)=>{
     if(resolve){
        setTimeout(()=>{
          console.log('this is task1!')
        },1000);
        resolve();
     }
  })
}

function task2(){
    setTimeout(()=>{
        console.log('this is task2!')
    },2000);
}


function task3(){
    setTimeout(()=>{
        console.log('this is task3!')
    },3000)
}

task1().then(task2).then(task3);

// or bad
function task1(){
    setTimeout(()=>{
        console.log('this is task1!') 
    },1000)
}

Promise.resolve().then(task1).then(task2).then(task3);


```
> - 虽然在第一个函数返回了一个Promise，but由于后面的异步操作并木有被Promise包装，所以并不会起任何作用，正确的写法是每一个异步操作都要被Promise包装

> - resolve()调用的时机不对，需要写在异步操作内部，上面那种写在异步操作外面，不会起任何作用。

```javascript

//good
function task1(){
	return new Promise((resolve,reject)=>{
        setTimeout(()=>{
            console.log('this is task1!');
            resolve();
        },1000);    
	})
}

function task2(){
    return new Promise((resolve,reject)=>{
        setTimeout(()=>{
            console.log('this is task2!');
            resolve();
        },2000);
    })
    
}


function task3(){
    return new Promise((resolve,reject)=>{
        setTimeout(()=>{
            console.log('this is task3!');
            resolve();
        },3000)
    })
    
}

task1().then(task2).then(task3);

// or good
function task1(fn){
    setTimeout(()=>{
        console.log('this is task1!');
        fn();
    },1000)
}

function task2(fn){
    setTimeout(()=>{
        console.log('this is task2!');
        fn();
    },2000)
}

function task3(fn){
    setTimeout(()=>{
        console.log('this is task3!');
        fn();
    },3000)
}

Promise.resolve()
        .then(()=>new Promise(resolve=>task1(resolve)))
        .then(()=>new Promise(resolve=>task2(resolve)))
        .then(()=>new Promise(resolve=>task3(resolve)));

```

- 各个task需要参数的传递

> 在Promise的链式调用中，各个task有可能存在相互依赖

```javascript
//如果resolve需要向后传递多个参数，需要以数组或者对象的形式传递
//bad
Promise.resolve(1,2,3)
       .then((value)=>console.log(value));     //1

//good
Promise.resolve([1,2,3])
       .then((value)=>console.log(value));    //[1,2,3]

//如果resolve需要向后只传递一个参数
//good
Promise.resolve(1)
       .then((value1)=>value1+1)
       .then((value2)=>value2+2)
       .then((value3)=>{
         console.log(value3+3)           //7
       });
```


### 异常捕获

> Promise (需要仔细看哟)

```javascript
//Promise无法捕获的异常
//bad
const p = new Promise((resolve, reject) => {
    setTimeout(() => {
        throw Error('false')
    })
})
p.then(result => {
    console.log(result) // 永远不会执行
}).catch(error => {
    console.log(error) // 永远不会执行
})
// 程序崩溃
// Uncaught Error: false


//good
const p = new Promise((resolve, reject) => {
     throw Error('false')
})
p.then(result => {
    console.log('结果:',result) // 永远不会执行
}).catch(error => {
    console.log('异常:',error) // 异常: Error: false
})


//or good
const p = new Promise((resolve, reject) => {
    setTimeout(() => {
        reject('false')
    })
})
p.then(result => {
    console.log('结果:',result) // 永远不会执行
}).catch(error => {
    console.log('异常:',error) // 异常: false
})


//good
const p1 = new Promise((resolve, reject) => {
    reject('false')
})
p1.then(result => {
    console.log('结果:',result) // 永远不会执行
}).catch(error => {
    console.log('异常:',error) // 异常: false
})

//or good
const p2 = new Promise((resolve, reject) => {
    resolve('ok')
})
p2.then(result => {
    return Promise.reject('false')
}).then(result => {
    console.log(result) // 永远不会执行
    return Promise.resolve('ok1') // 永远不会执行
}).then(result => {
    console.log('结果:',result) // 永远不会执行
}).catch(error => {
    console.log('异常:',error) // 异常: false
})

//bad
const p3 = new Promise((resolve, reject) => {
    resolve('ok')
})
p3.then(result => {
    return throw new Error('fail!')
}).then(result => {
    console.log('结果:',result) // 永远不会执行
    return Promise.resolve('ok1') // 永远不会执行
}).then(result => {
    console.log('结果:',result) // 永远不会执行
}).catch(error => {
    console.log('异常:',error)
})
 // 程序崩溃
 // Uncaught SyntaxError: Unexpected token 'throw'

//good
const p3 = new Promise((resolve, reject) => {
    resolve('ok')
})
p3.then(result => {
    throw new Error('fail!')
}).then(result => {
    console.log(result) // 永远不会执行
    return Promise.resolve('ok1') // 永远不会执行
}).then(result => {
    console.log('结果:',result) // 永远不会执行
}).catch(error => {
    console.log('异常:',error) // 异常: Error: fail!
})
```

> 优雅的async + await：

```javascript
// bad
handlePreventStatus = async () => {
  this.showLoading()
  //返回一个promise
  let res = await this.getPreventStatus();
  //your coding...
  
  this.hideLoading()
}

//good
handlePreventStatus = async () => {
 this.showLoading()
 try {
  //返回一个promise
  let res = await this.getPreventStatus();
  //your coding...
 }
 catch (error) {
 // 抛出异常
 console.log(error);
 }
 finally {
  // 无论try还是catch都会走到这里，个人根据自己的需求视情况coding
  this.hideLoading()
 }
}
```


 ## 写在最后
 想揭开Promise的神秘面纱可以挪步 我的另一篇文章【Promise踩坑记】
  








